Workbook

Sheet Frontpage
B19: Armoury | H19: Weapon | L19: Food
A20: Helmet: | B20: Reinforced Helmet | C20: {=IFERROR(INDEX(Armour!C:C, MATCH(B20, Armour!B:B, 0)), 0)} -> 0.13 | D20: {=IFERROR(INDEX(Armour!D:D, MATCH(B20, Armour!B:B, 0)), 0)} -> 0.09 | E20: {=IFERROR(INDEX(Armour!E:E, MATCH(B20, Armour!B:B, 0)), 0)} -> Melee 3 | G20: Primary | H20: Type | I20: Secondary
A21: Chest: | B21: Reinforced Chest | C21: {=IFERROR(INDEX(Armour!C:C, MATCH(B21, Armour!B:B, 0)), 0)} -> 0.58 | D21: {=IFERROR(INDEX(Armour!D:D, MATCH(B21, Armour!B:B, 0)), 0)} -> 0.32 | E21: {=IFERROR(INDEX(Armour!E:E, MATCH(B21, Armour!B:B, 0)), 0)} -> Melee 3 | F21: Attack | G21: {=IFERROR(INDEX(Weapon!C:C, MATCH(H21, Weapon!B:B, 0)), 0)} -> Impaling 16 - 19 | H21: Flint Spear | I21: {=IFERROR(INDEX(Weapon!H:H, MATCH(H21, Weapon!B:B, 0)), 0)} -> Impale 18 - 22 | K21: Regen per Sec | L21: {=IFERROR(INDEX(Foods!C:C, MATCH(L20, Foods!B:B, 0)), 0)} -> 0
A22: Legs: | B22: Reinforced Leg | C22: {=IFERROR(INDEX(Armour!C:C, MATCH(B22, Armour!B:B, 0)), 0)} -> 0.08 | D22: {=IFERROR(INDEX(Armour!D:D, MATCH(B22, Armour!B:B, 0)), 0)} -> 0.07 | E22: {=IFERROR(INDEX(Armour!E:E, MATCH(B22, Armour!B:B, 0)), 0)} -> Melee 3 | F22: Speed | G22: {=IFERROR(INDEX(Weapon!D:D, MATCH(H21, Weapon!B:B, 0)), 0)} -> 1 sec | H22: {=IFERROR(INDEX(Weapon!M:M, MATCH(H21, Weapon!B:B, 0)), 0)} | I22: {=IFERROR(INDEX(Weapon!I:I, MATCH(H21, Weapon!B:B, 0)), 0)} -> 0.7 sec | K22: Duration | L22: {=IFERROR(INDEX(Foods!D:D, MATCH(L20, Foods!B:B, 0)), 0)} -> 0
A23: Shield: | B23: Superior Shield | C23: {=IFERROR(INDEX(Shields!C:C, MATCH(B23, Shields!B:B, 0)), 0)} -> 223 Hits | D23: {=IFERROR(INDEX(Shields!D:D, MATCH(B23, Shields!B:B, 0)), 0)} -> 0.14 | E23: {=IFERROR(INDEX(Shields!E:E, MATCH(B23, Shields!B:B, 0)), 0)} -> Melee 5 | F23: Movement | G23: {=IFERROR(INDEX(Weapon!E:E, MATCH(H21, Weapon!B:B, 0)), 0)} -> 0.25 | H23: {=IFERROR(INDEX(Weapon!N:N, MATCH(H21, Weapon!B:B, 0)), 0)} | I23: {=IFERROR(INDEX(Weapon!J:J, MATCH(H21, Weapon!B:B, 0)), 0)} -> 0.25 | K23: Hunger | L23: {=IFERROR(INDEX(Foods!E:E, MATCH(L20, Foods!B:B, 0)), 0)} -> 0
A24: Dmg Mitigation: | B24: =1 - (( 1 - C20 ) * ( 1 - C21 ) * ( 1 - C22 )) -> 0.663832 | F24: Stability Dmg | G24: {=IFERROR(INDEX(Weapon!F:F, MATCH(H21, Weapon!B:B, 0)), 0)} -> - | H24: {=IFERROR(INDEX(Weapon!O:O, MATCH(H21, Weapon!B:B, 0)), 0)} | I24: {=IFERROR(INDEX(Weapon!K:K, MATCH(H21, Weapon!B:B, 0)), 0)} -> -
A25: Health: | B25: =100 / (( 1 - C20 ) * ( 1 - C21 ) * ( 1 - C22 )) -> 297.47031 | F25: Stamina | G25: {=IFERROR(INDEX(Weapon!G:G, MATCH(H21, Weapon!B:B, 0)), 0)} -> ⚡20 | H25: {=IFERROR(INDEX(Weapon!P:P, MATCH(H21, Weapon!B:B, 0)), 0)} | I25: {=IFERROR(INDEX(Weapon!L:L, MATCH(H21, Weapon!B:B, 0)), 0)} -> ⚡20
A26: Stability Mitigation: | B26: =1 - (( 1 - D20 ) * ( 1 - D21 ) * ( 1 - D22 )) -> 0.424516 | H26: Effectivness
G27: Infantry: | H27: {=IFERROR(INDEX(Weapon!Q:Q, MATCH(H21, Weapon!B:B, 0)), "")} | I27: {=IFERROR(INDEX(Extras!I:I, MATCH(H27, Extras!H:H, 0)), "")}
G28: NPC's: | H28: {=IFERROR(INDEX(Weapon!R:R, MATCH(H21, Weapon!B:B, 0)), "")} -> 🛡️28% | I28: {=IFERROR(INDEX(Extras!I:I, MATCH(H28, Extras!H:H, 0)), "")}
B29: NPC's | G29: Mounted Units: | H29: {=IFERROR(INDEX(Weapon!S:S, MATCH(H21, Weapon!B:B, 0)), "")} -> 40 | I29: {=IFERROR(INDEX(Extras!I:I, MATCH(H29, Extras!H:H, 0)), "")}
B30: Wolf
A31: NPC's Health | B31: {=IFERROR(INDEX(NPCs!C:C, MATCH(B30, NPCs!B:B, 0)), 0)} -> 225 | C31: ❤️
A32: Hits taken | B32: =IFERROR(B25/C31, 0) -> 0 | C32: Armour
A33: Needed hits | B33: =IFERROR(B31/H25, 0) -> 0 | C33: Weapon

Sheet Foods
A1: ID | B1: Type | C1: Effect | D1: Effect | E1: Hunger | F1: Food Type
A2: F100 | B2: Berries | C2: 1.0❤️ | D2: 30 sec | E2: 🍴3 | F2: Berry
A3: F101 | B3: Bloodberry Field Bar | C3: 1.5❤️ | D3: 2 min | E3: 🍴15 | F3: Berry
A4: F102 | B4: Boiled Cabbage | C4: 1.0❤️ | D4: 30 sec | E4: 🍴80 | F4: Produce
A5: F103 | B5: Boiled Eggs | C5: 2.0❤️ | D5: 45 sec | E5: 🍴35 | F5: Produce
A6: F104 | B6: Egg Tarte | C6: 1.0❤️ | D6: 8 min | E6: 🍴100 | F6: Produce
A7: F105 | B7: Grilled Whitefish | C7: 1.5❤️ | D7: 5 sec | E7: 🍴15 | F7: Fish
A8: F106 | B8: Lost Bread | C8: 0.5❤️ | D8: 10 min | E8: 🍴60 | F8: Wheat
A9: F107 | B9: Mead | C9: 1.0❤️ | D9: 3 min | E9: 🍴20 | F9: Berry
A10: F108 | B10: Pemmikan | C10: 2.0❤️ | D10: 3 min | E10: 🍴25 | F10: Common Meat
A11: F109 | B11: Plain Alemette | C11: 2.0❤️ | D11: 50 sec | E11: 🍴30 | F11: Produce
A12: F110 | B12: Roasted Game | C12: 1.5❤️ | D12: 4 min | E12: 🍴30 | F12: Deer Meat
... A16: F114 | B16: Water Pie | C16: 1.5❤️ | D16: 15 min | E16: 🍴70 | F16: Common Meat

Sheet Armour
A1: ID | B1: Type | C1: Dmg Mitigation | D1: Stb Mitigation | E1: Requirements | F1: Bodypart | G1: Temperature Mitigation | K1: Armour Class | L1: Heavy Armour | M1: Projectile Stagger immunity | N1: Projectile Deflection | O1: Piercing Vulnerability
A2: A100 | B2: Common Bottoms | C2: 0 | D2: 0 | E2: - | F2: Leg | G2: 0 | H2: Clothing | K2: Heavy Chest | L2: Yes | M2: Yes | N2: Yes | O2: No
A3: A101 | B3: Common Garment | C3: 0 | D3: 0 | E3: - | F3: Chest | G3: 0 | H3: Clothing | K3: Heavy | L3: Yes | M3: No | N3: No | O3: No
A4: A102 | B4: Crude Chest | C4: 0.11 | D4: 0 | E4: - | F4: Chest | G4: - | H4: Armour | K4: Reinforced Chest | L4: Yes | M4: Yes | N4: No | O4: Yes
A5: A103 | B5: Crude Helmet | C5: 0.04 | D5: 0 | E5: - | F5: Head | G5: - | H5: Armour | K5: Reinforced | L5: Yes | M5: No | N5: No | O5: Yes
A6: A104 | B6: Crude Leg | C6: 0.01 | D6: 0 | E6: - | F6: Leg | G6: - | H6: Armour | K6: Light | L6: No | M6: No | N6: No | O6: Yes
A7: A106 | B7: Heavy Chest | C7: 0.64 | D7: 0.35 | E7: Melee 5 | F7: Chest | G7: - | H7: Armour
A8: A107 | B8: Heavy Helmet | C8: 0.16 | D8: 0.11 | E8: Melee 5 | F8: Head | G8: - | H8: Armour | K8: Heavy Armour: Prevents arming bows and spears.
A9: A108 | B9: Heavy Leg | C9: 0.1 | D9: 0.08 | E9: Melee 5 | F9: Leg | G9: - | H9: Armour | K9: Projectile Stagger Immunity: Does not get staggered by projectiles.
A10: A110 | B10: Light Chest | C10: 0.36 | D10: 0.24 | F10: Chest | G10: - | H10: Armour | K10: Projectile Deflection: Can deflect Crude Shortbow Arrows , Shortbow Arrows , Longbow Arrows , and Javelin . Deflection chance is higher if projectiles are coming from in front.
A11: A111 | B11: Light Helmet | C11: 0.09 | D11: 0.06 | F11: Head | G11: - | H11: Armour | K11: Piercing Vulnerability: Halves the total mitigation against Piercing damage type.
A12: A112 | B12: Light Leg | C12: 0.06 | D12: 0.04 | F12: Leg | G12: - | H12: Armour
A13: A114 | B13: Reinforced Chest | C13: 0.58 | D13: 0.32 | E13: Melee 3 | F13: Chest | G13: - | H13: Armour
A14: A115 | B14: Reinforced Helmet | C14: 0.13 | D14: 0.09 | E14: Melee 3 | F14: Head | G14: - | H14: Armour
A15: A116 | B15: Reinforced Leg | C15: 0.08 | D15: 0.07 | E15: Melee 3 | F15: Leg | G15: - | H15: Armour
A16: A117 | B16: Light Garment | C16: 0.04 | D16: 0.02 | F16: Chest | G16: 0.5 | H16: Clothing | K16: Damage Mitigation
A17: A118 | B17: Light Bottoms | C17: 0.02 | D17: 0.01 | F17: Leg | G17: 0.25 | H17: Clothing | K17: Damage mitigation reduces the amount of taken damage. It is multiplicative and each quality level provides 10%, 20%, 30% additional damage mitigation over base damage mitigation respectively.
K18: Total damage mitigation is calculated following this formula:
K19: TotalDmgMit = 1 - (( 1 - (DmgMitA * QltyLvLMult) ) * ( 1 - (DmgMitB * QltyLvLMult) ) * ( 1 - (DmgMitC * QltyLvLMult) ))
K21: Stability Mitigation
K22: Stability mitigation reduces the stagger time while in combat. It is addictive and not affected by armour quality.
K23: Total stability mitigation is calculated following this formula:
K24: TotalStbMit = StbMitA + StbMitB + StbMitC
K26: Temperature Mitigation
K27: Temperature mitigation reduces the heat transfer amount per second, slowing both cooling down and heating up. Total temperature mitigation is addictive and not affected by armour quality.
K28: Total temperature mitigation is calculated following this formula:
K29: TotalTmpMit = TmpMitA + TmpMitB + TmpMitC

Sheet Shields
A1: ID | B1: Type | C1: Durability | D1: Stability Loss pH | E1: Requirements
A2: SH100 | B2: Crude Shield | C2: 223 Hits | D2: 0.3 | E2: -
A3: SH101 | B3: Iron Shield | C3: 223 Hits | D3: 0.16 | E3: Melee 3
A4: SH102 | B4: Light Targe | C4: 223 Hits | D4: 0.24 | E4: -
A5: SH103 | B5: Superior Shield | C5: 223 Hits | D5: 0.14 | E5: Melee 5
A7: Missile damage deals 50% less guard stamina damage to shields.

Sheet Tool
A1: ID | B1: Type | C1: Effectiveness | D1: Durability
A2: T100 | B2: Alliance Banner | C2: 1 | D2: -
A3: T101 | B3: Bronze Axe | C3: 0.66 | D3: 400
A4: T102 | B4: Bronze Knife | C4: 0.66 | D4: 160
A5: T103 | B5: Bronze Pickaxe | C5: 0.75 | D5: 400
A6: T104 | B6: Fishing Pole | C6: 1 | D6: 200
A7: T105 | B7: Flint Hammer | C7: 1 | D7: 134
A8: T106 | B8: Flint Knife | C8: 0.5 | D8: 80
A9: T107 | B9: Flint Pickaxe | C9: 0.5 | D9: 200
A10: T108 | B10: Hands | C10: 1 | D10: -
A11: T109 | B11: Iron Axe | C11: 0.8 | D11: 800
A12: T110 | B12: Iron Broadaxe | C12: 1 | D12: 400
A13: T111 | B13: Iron Hammer | C13: 1 | D13: 267
A14: T112 | B14: Iron Hoe | C14: 1 | D14: 100
A15: T113 | B15: Iron Knife | C15: 1 | D15: 320
A16: T114 | B16: Iron Pickaxe | C16: 1 | D16: 800
A17: T115 | B17: Iron Scythe | C17: 1 | D17: 200
A18: T116 | B18: Rope | C18: 1 | D18: -
A19: T117 | B19: Stone Axe | C19: 0.5 | D19: 200

Sheet Weapon
B1: Type | C1: Attack 1 | D1: Attacktime 1 | E1: Movement 1 | F1: Ability 1 | G1: Stamina 1 | H1: Attack 2 | I1: Attacktime 2 | J1: Movement 2 | K1: Ability 2 | L1: Stamina 2 | M1: Attack 3 | N1: Attacktime 3 | O1: Movement 3 | P1: Ability 3 | Q1: Stamina 3 | R1: Stability Loss | S1: Durability | T1: Requirements
A2: W100 | B2: Bronze Short Sword | C2: Slashing 27 - 33 | D2: 1 sec | E2: 0.25 | F2: - | G2: ⚡20 | H2: Slashing 17-20 | I2: 0.75 sec | J2: 0.25 | K2: - | L2: ⚡15 | M2: Slashing 40-49 | N2: 1.47 sec | O2: 0.25 | P2: Damage to guard: 10% | Q2: 0.3 | R2: 🛡️32% | S2: 100 | T2: -
A3: W101 | B3: Bronze Spear | C3: Impale 22 - 27 | D3: 1 sec | E3: 0.25 | F3: - | G3: ⚡20 | H3: Impale 45 - 55 | I3: 0.7 sec | J3: 0.25 | K3: - | L3: ⚡20 | R3: 🛡️28% | S3: 67 | T3: Cannot be used with Reinforced Armour or Heavy Armour
A4: W102 | B4: Burning Oil | C4: Burning 45 - 55 | D4: 0.34 sec | E4: 66.5% | F4: Range 5m | G4: ⚡10 | H4: - | I4: - | J4: - | K4: - | L4: ⚡- | R4: 🛡️- | S4: - | T4: -
A5: W103 | B5: Crude Short Sword | C5: Slashing 21 - 26 | D5: 1 sec | E5: 0.25 | F5: - | G5: ⚡20 | H5: Slashing 13 - 16 | I5: 0.75 sec | J5: 0.25 | K5: - | L5: ⚡15 | M5: Slashing 32-39 | N5: 1.47 sec | O5: 0.25 | P5: Damage to guard: 6% | Q5: 0.3 | R5: 🛡️36% | S5: 100 | T5: -
A6: W104 | B6: Crude Shortbow | C6: Missile 49 - 60 | D6: 1.17 sec | E6: 0.4 | F6: Range 27m , Inaccuracy 0m - 1m , Max Accuracy 1s | G6: ⚡8 | H6: Missile 49 - 60 | I6: 1.17 sec | J6: 0.6 | K6: Range 16m , Inaccuracy 1.5m - 3.5m , Max Accuracy 1s | L6: ⚡8 | R6: 🛡️- | S6: 167 | T6: Bows cannot be armed while wearing reinforced armour or heavy armour.
A7: W105 | B7: Crude Throwing Axe | C7: Slashing 13 - 16 | D7: 0.2 sec | E7: - | F7: It always staggers the target on impact even if it is wearing heavy armour. | G7: ⚡8 | H7: - | I7: - | J7: - | K7: - | L7: ⚡- | R7: 🛡️- | S7: - | T7: -
A8: W106 | B8: Fine Longsword | C8: Piercing 49 - 60 | D8: 1 sec | E8: 0.25 | F8: - | G8: ⚡20 | H8: Piercing 35 - 42 | I8: 0.75 sec | J8: 0.25 | K8: - | L8: ⚡15 | M8: Piercing 81 - 99 | N8: 1.75 sec | O8: 0.25 | P8: Damage to guard: 15% | Q8: 0.3 | R8: 🛡️24% | S8: 100 | T8: Melee 6
A9: W107 | B9: Fine Short Sword | C9: Slashing 40 - 49 | D9: 1 sec | E9: 0.25 | F9: - | G9: ⚡20 | H9: Slashing 26 - 31 | I9: 0.75 sec | J9: 0.25 | K9: - | L9: ⚡15 | M9: Slashing 60 - 73 | N9: 1.47 sec | O9: 0.25 | P9: Damage to guard: 15% | Q9: 0.3 | R9: 🛡️28% | S9: 100 | T9: Melee 5
A10: W108 | B10: Flint Spear | C10: Impaling 16 - 19 | D10: 1 sec | E10: 0.25 | F10: - | G10: ⚡20 | H10: Impale 18 - 22 | I10: 0.7 sec | J10: 0.25 | K10: - | L10: ⚡20 | R10: 🛡️28% | S10: 40 | T10: Cannot be used with Reinforced Armour or Heavy Armour
A11: W109 | B11: Iron Longsword | C11: Piercing 40 - 49 | D11: 1 sec | E11: 0.25 | F11: - | G11: ⚡20 | H11: Piercing 32 - 39 | I11: 0.75 sec | J11: 0.25 | K11: - | L11: ⚡15 | M11: Piercing 73 - 90 | N11: 1.75 sec | O11: 0.25 | P11: Damage to guard: 15% | Q11: 0.3 | R11: 🛡️24% | S11: 100 | T11: Melee 4
A12: W110 | B12: Iron Mace | C12: Crush 25 - 30 | D12: 1 sec | E12: 0.25 | F12: Stability Damage 3.75% | G12: ⚡20 | R12: 🛡️28% | S12: 100 | T12: Melee 5
A13: W111 | B13: Iron Short Sword | C13: Slashing 31 - 38 | D13: 1 sec | E13: 0.25 | F13: - | G13: ⚡20 | H13: Slashing 20 - 25 | I13: 0.75 sec | J13: 0.25 | K13: - | L13: ⚡15 | M13: Slashing 46 - 57 | N13: 1.47 sec | O13: 0.25 | P13: Damage to guard: 15% | Q13: 0.3 | R13: 🛡️28% | S13: 100 | T13: Melee 3
A14: W112 | B14: Iron Spear | C14: Impale 29 - 36 | D14: 1 sec | E14: 0.25 | F14: - | G14: ⚡20 | H14: Impale 67 - 82 | I14: 0.7 sec | J14: 0.25 | K14: - | L14: ⚡20 | R14: 🛡️28% | T14: -
A15: W113 | B15: Javelin | C15: Slashing 25 - 30 | D15: 1 sec | E15: 0.25 | F15: - | G15: ⚡10 | H15: Missile 135 - 165 | I15: 0.7 sec | J15: 0.25 | K15: Range 20m | L15: ⚡10 | R15: 🛡️28% | S15: 100 | T15: Melee 2 , Ranged 4 Cannot be used with Reinforced Armour or Heavy Armour
A16: W114 | B16: Longbow | C16: Missile 117 - 144 | D16: 1.17 sec | E16: 0.6 | F16: Range 34m , Inaccuracy 0m - 3m, Max Accuracy 1s | G16: ⚡8 | H16: Missile 94 - 115 | I16: 1.17 sec | J16: 0.7 | K16: Range 35m , Inaccuracy 2m - 4m , Max Accuracy 1s | L16: ⚡10 | R16: 🛡️- | S16: 167 | T16: Ranged 5, Bows cannot be armed while wearing reinforced armour or heavy armour.
A17: W115 | B17: Masterwork Short Sword | C17: Slashing 49 - 60 | D17: 1 sec | E17: 0.25 | F17: - | G17: ⚡20 | H17: Slashing 34 - 41 | I17: 0.75 sec | J17: 0.25 | K17: - | L17: ⚡15 | M17: Slashing 73 - 90 | N17: 1.47 sec | O17: 0.25 | P17: Damage to guard: 15% | Q17: 0.3 | R17: 🛡️28% | S17: 100 | T17: Melee 7
A18: W116 | B18: Oil Flask | C18: Siege 10 - 13 | D18: 0.7 sec | E18: - | F18: Range 6m , No Damage to stone structures | G18: ⚡10 | H18: - | I18: - | J18: - | K18: - | L18: ⚡- | R18: 🛡️- | S18: - | T18: -
A19: W117 | B19: Quality Throwing Axe | C19: Slashing 22 - 27 | D19: 0.2 sec | E19: - | F19: It always staggers the target on impact even if it is wearing heavy armour. | G19: ⚡8 | H19: - | I19: - | J19: - | K19: - | L19: ⚡- | R19: 🛡️- | S19: - | T19: -
A20: W118 | B20: Shortbow | C20: Missile 76 - 93 | D20: 1.17 sec | E20: 0.4 | F20: Range 27m , Inaccuracy 0m - 1m , Max Accuracy 1s | G20: ⚡8 | H20: Missile 76 - 93 | I20: 1.17 sec | J20: 0.6 | K20: Range 16m , Inaccuracy 1.5m - 3.5m , Max Accuracy 1s | L20: ⚡8 | R20: 🛡️- | S20: 167 | T20: Ranged 3, Bows cannot be armed while wearing reinforced armour or heavy armour.
A21: W119 | B21: Superior Longsword | C21: Piercing 54 - 66 | D21: 1 sec | E21: 0.25 | F21: - | G21: ⚡20 | H21: Piercing 37 - 46 | I21: 0.75 sec | J21: 0.25 | K21: - | L21: ⚡15 | M21: Piercing 87 - 106 | N21: 1.75 sec | O21: 0.25 | P21: Damage to guard: 15% | Q21: 0.3 | R21: 🛡️24% | S21: 100 | T21: Melee 7
A22: W120 | B22: Superior Short Sword | C22: Slashing 45 - 55 | D22: 1 sec | E22: 0.25 | F22: - | G22: ⚡20 | H22: Slashing 29 - 36 | I22: 0.75 sec | J22: 0.25 | K22: - | L22: ⚡15 | M22: Slashing 67 - 82 | N22: 1.47 sec | O22: 0.25 | P22: Damage to guard: 15% | Q22: 0.3 | R22: 🛡️28% | S22: 100 | T22: Melee 6
A23: W121 | B23: Superior Shortbow | C23: Missile 94 - 115 | D23: 1.17 sec | E23: 0.1 | F23: Range 27m , Inaccuracy 0m - 1m , Max Accuracy 1s | G23: ⚡8 | H23: Missile 94 - 115 | I23: 1.17 sec | J23: 0.3 | K23: Range 16m , Inaccuracy 1.5m - 3.5m , Max Accuracy 1s | L23: ⚡8 | R23: 🛡️- | S23: 167 | T23: Ranged 5, Bows cannot be armed while wearing reinforced armour or heavy armour.
A24: W122 | B24: Superior Spear | C24: Impaling 46 - 57 | D24: 1 sec | E24: 0.25 | F24: - | G24: ⚡20 | H24: Impaling 76 - 93 | I24: 0.7 sec | J24: 0.25 | K24: - | L24: ⚡20 | R24: 🛡️28% | S24: 134 | T24: Melee 5 , Ranged 5 , Cannot be used with Reinforced Armour or Heavy Armour
A25: W123 | B25: Torch | C25: Slashing 9 - 11 | D25: 1.1 sec | E25: - | F25: - | G25: ⚡10 | H25: Siege 3 - 4 | I25: 0.4 sec | J25: - | K25: Range 6m | L25: ⚡10 | R25: 🛡️- | S25: - | T25: -
A26: W124 | B26: Trap | C26: - | D26: - | E26: - | F26: - | G26: ⚡- | H26: - | I26: - | J26: - | K26: - | L26: ⚡- | R26: 🛡️- | S26: - | T26: -
A27: W125 | B27: Iron Broadaxe | C27: Cleaving 25 - 30 | D27: 1 sec | E27: 0.25 | F27: Shield durability loss multiplier x20 ; Armour damage multiplayer x7.5 | G27: ⚡20 | R27: 🛡️28% | S27: 400 | T27: Melee 5
A28: W126 | B28: Defensive Stone | C28: Crush 135 - 165 | D28: 0.1 sec | E28: 0.55 | F28: Damage to Stability 50% , Range 5m | G28: ⚡10 | H28: - | I28: - | J28: - | K28: - | L28: - | R28: 🛡️- | S28: - | T28: -
A29: W127 | B29: Bronze Knife | C29: Slashing 18-22 | D29: 1.1 sec | E29: 0.25 | G29: ⚡10 | S29: 160
A30: W128 | B30: Flint Knife | C30: Slashing 13-16 | D30: 1.1 sec | E30: 0.25 | G30: ⚡10 | S30: 80
A31: W129 | B31: Iron Knife | C31: Slashing 22 - 27 | D31: 1.1 sec | E31: 0.25 | G31: ⚡10 | S31: 320
A33: AI Note, do not include in Discord bot: Movement speed only changes for bows due to how they can be held. Melee weapons have the same movement speed to all times.
A36: Damage Type | B36: Infantry | C36: NPC | D36: Mounted Unit | E36: Light Structure | F36: Heavy Structure | G36: Vehicle
A37: Slashing | B37: 0.75 | C37: 1 | D37: 0.5 | E37: 0.1 | F37: 0 | G37: 0
A38: Piercing | B38: 0.75 | C38: 1 | D38: 0.5 | E38: 0.1 | F38: 0 | G38: 0
A39: Missile | B39: 1 | C39: 0.5 | D39: 0.25 | E39: 0 | F39: 0 | G39: 0
A40: Siege | B40: 0.3 | C40: 0.3 | D40: 0.3 | E40: 1 | F40: 1 | G40: 5
A41: Animal | B41: 1 | C41: 1 | D41: 0.5 | E41: 0.1 | F41: 0 | G41: 0.1
A42: Cleaving | B42: 0.75 | C42: 1 | D42: 0.5 | E42: 1 | F42: 0 | G42: 1
A43: Crushing | B43: 0.75 | C43: 1 | D43: 0.5 | E43: 0.1 | F43: 0 | G43: 0.33
...

Sheet Vehicle
A1: ID | B1: Type | C1: Health | D1: Seats | E1: Speed | F1: Sprint Speed | G1: Sprint Duration | H1: Road Bonus | I1: Damage | J1: Description
A2: V100 | B2: Battering Ram | C2: 460 | D2: 4 | E2: 1.5 m /s | F2: 7.5 m/s | G2: 20 Seconds | H2: 1x | I2: 150 Siege | J2: The Battering Ram is a battering ram used for ramming structures. It requires 4 people to use. The ram must be moving at least 60% of its maximum velocity for its damage to be applied on impact. Any players hit by the ram will be killed instantly regardless of health.
A3: V101 | B3: Caravan | C3: 128 | E3: 4 m/s | F3: 6 m/s | G3: 6 Seconds | H3: 1.2x | J3: A Caravan is a horse-drawn vehicle that can be used for transporting avatars, supplies or used to deploy a build site for a Fortress Keep or Large Camp. It has a large inventory which can be used for transporting barreled goods long distances. To deploy a build site from a caravan, use the designated button in the caravan's interaction menu and select the desired structure. This will activate build mode, enabling you to position your selected structure.
A4: V102 | B4: Catapult | C4: 315 | D4: 4 | E4: 1.5 m/s | H4: 1x | I4: 45 - 55 Siege | J4: The Catapult is a siege vehicle used to fire Catapult Boulder at enemy structures. It requires 4 people to move. It can be operated by 2 players, with one player operating the crank for rearming, while another player operates the lever for firing. Catapult Boulders will deal damage to both structures and vehicles, with players being killed instantly when hit.
A5: V103 | B5: Donkey | C5: 80 | D5: 1 | E5: 4.55 m/s | F5: 6.825 m/s | G5: 20 Seconds | H5: 1x | I5: 20 Default
A6: V104 | B6: Hand Cart | C6: 80 | D6: 1 | E6: 3.75 m/s | F6: 4.5 m/s | G6: 1m 40sec | H6: 1.2x | J6: Hand Cart is a basic vehicle used for transportation of resources. It's currently the only vehicle that can be used in the underworld to support mining activities.
A7: V105 | B7: Heavy Battering Ram | C7: 1050 | D7: 6 | E7: 0.75 m/s | F7: 3.75 m/s | G7: 20 seconds | H7: 1x | I7: 75 Siege | J7: The Heavy Battering Ram is a battering ram used for ramming structures. It requires 6 people to move with 4 of the vehicles operators being protected by the roof from arrow fire. Players inside the ram can still be melee attacked.
A8: V106 | B8: Horse | C8: 200 | D8: 2 | E8: 4.4 m/s | F8: 8.8 m/s | G8: 20 Seconds | H8: 1.3x | I8: 20 Slashing
A9: V107 | B9: Resource Wagon | C9: 200 | D9: 2 | E9: 4 m/s | F9: 6 m/s | G9: 6 Seconds | H9: 1.2x | J9: A Resource Wagon is a horse-drawn vehicle that can be used for transporting various resources. The wagon itself has two seats for passengers.
A10: V108 | B10: Scorpion | C10: 100 | D10: 1 | I10: 216 - 264 Piercing | J10: The Scorpion is a defensive anti-infantry siege weapon that can be deployed on foundations.
A11: V109 | B11: Siege Ladder | C11: 200 | D11: 2 | E11: 3 m/s | H11: 1x | J11: In order to move and turn both players must work together either pushing forward or backwards. In order to turn left or right both players invert push direction from the other side. The ladder can rotate on the spot, or translate left and right if both players share left and right inputs.
A12: V110 | B12: Siege Tower | C12: 3220 | D12: 8 | E12: 0.5 m&s | F12: 2.5 m/s | G12: 20 Seconds | H12: 1x | J12: The Siege Tower is a siege vehicle used to protect attackers as they approach and scale walls during an assault. It requires 8 people to move.
A13: V111 | B13: Small Boat | C13: 200 | D13: 3 | E13: 1.75 m/s | J13: The Small Boat is a water vehicle that can hold up to 3 people.
A14: V112 | B14: Cargo Ship | C14: 600 | D14: 8 | E14: 2.5 m/s | J14: Cargo Ship is a boat variant built at a Shipyard that can be used to move larger numbers of people, items, and up to 2 from a small list of vehicles across waterways. Players can stand, eat and walk around on the deck while the ship is moving. It can be docked with a Shipdock for repairs and storage.
A15: V113 | B15: Makeshift Battering Ram | C15: 276 | D15: 4 | E15: 1.5 m/s | F15: 7 m/s | G15: 20 Seconds | H15: 1x | I15: 75 Siege | J15: The Makeshift Battering Ram is a light battering ram used for ramming structures. It can be built only after 3 Hours into an age. It requires 4 people to use. The ram must be moving at least 60% of its maximum velocity for its damage to be applied on impact. Any players hit by the ram will be killed instantly regardless of health.

Sheet Structure
A1: ID | B1: Type
A2: S100 | B2: Anvil
A3: S101 | B3: Aqueduct Parts
A4: S102 | B4: Aqueduct Pump
A5: S103 | B5: Armour Rack
A6: S104 | B6: Banquet Table
A7: S105 | B7: Beacon Tower
A8: S106 | B8: Bear Den
A9: S107 | B9: Bellow
A10: S108 | B10: Camp Gate
A11: S109 | B11: Camp Palisade
A12: S110 | B12: Canal
... A78: S176 | B78: Wind Mill

Sheet NPCs
A1: ID | B1: Type | C1: Health | D1: Behaivour | E1: Damage | F1: Harvest Hits | G1: Extras | H1: Health Regen
A2: N100 | B2: Bat | C2: 40 | D2: Aggressive | E2: 25 | F2: 2 | H2: 3 per sec , 10min delay
A3: N101 | B3: Bear | C3: 425 | D3: Aggressive | E3: 45 | H3: 10 per sec, 10min delay
A4: N102 | B4: Boar | C4: 35 | D4: Aggressive | E4: 20 | F4: 3 | H4: 3 per sec , 10min delay
A5: N103 | B5: Chicken | C5: 10 | D5: Passive | E5: 0 | F5: 1
A6: N104 | B6: Deer | C6: 35 | D6: Passive | E6: 0 | F6: 2
A7: N105 | B7: Dire Raven | C7: 35 | D7: Aggressive | E7: 35 | F7: 3 | H7: 3 per sec , 10min delay
A8: N106 | B8: Donkey Foal | C8: 80 | D8: Passive | E8: 0
A9: N107 | B9: Horse Foal | C9: 30 | D9: Passive | E9: 0
A10: N108 | B10: Manadyr | C10: 3000 | D10: Aggressive | E10: 30 - 75 | F10: 14 | G10: Also deals Missle damage, Stun and Stability damage. Ranged and Melee attacks | H10: 3 per sec, 10min delay
A11: N109 | B11: Rabbit | C11: 10 | D11: Passive | E11: 0 | F11: 1
A12: N110 | B12: Reaver Bandit | C12: 475 | D12: Aggressive | E12: 35 | G12: Does Slash damage | H12: 3 per sec, 10min delay
A13: N111 | B13: Reaver Highwayman (Melee) | C13: 275 | D13: Aggressive | E13: 22 | G13: Does Slash damage | H13: 3 per sec, 10min delay
A14: N112 | B14: Reaver Highwayman (Ranged) | C14: 200 | D14: Aggressive | E14: 15 - 30 | G14: Does Missile damage, also Stun damage | H14: 3 per sec, 10min delay
A15: N113 | B15: Stonwulfe | C15: 1000 | D15: Aggressive | E15: 60 | F15: 12 | G15: Also deals Stund damage | H15: 3 per sec , 10min delay
A16: N114 | B16: Wolf | C16: 225 | D16: Aggressive | E16: 30 | F16: 4 | H16: 3 per sec , 10min delay
A17: N115 | B17: Wolf (Cave) | C17: 375 | D17: Aggressive | E17: 30 | F17: 8 | H17: 3 per sec , 10min delay

Sheet Extras
A1: ID | B1: Amount | D1: ID | E1: Numbers | G1: ID | H1: Type | I1: Numbers
A2: P001 | B2: 0.01 | D2: No001 | E2: 1 | G2: Ef100 | H2: Very Effective | I2: 100%+
A3: P002 | B3: 0.02 | D3: No002 | E3: 2 | G3: Ef101 | H3: Effective | I3: 100%
A4: P003 | B4: 0.03 | D4: No003 | E4: 3 | G4: Ef102 | H4: Reduced | I4: 50-99%
A5: P004 | B5: 0.04 | D5: No004 | E5: 4 | G5: Ef103 | H5: Very Reduced | I5: 1-49%
A6: P005 | B6: 0.05 | D6: No005 | E6: 5 | G6: Ef104 | H6: No Damage | I6: 0%
A7: P006 | B7: 0.06 | D7: No006 | E7: 6
A8: P007 | B8: 0.07 | D8: No007 | E8: 7
A9: P008 | B9: 0.08 | D9: No008 | E9: 8
A10: P009 | B10: 0.09 | D10: No009 | E10: 9
A11: P010 | B11: 0.1 | D11: No010 | E11: 10
A12: P011 | B12: 0.11 | D12: No011 | E12: 11
A13: P012 | B13: 0.12 | D13: No012 | E13: 12
A14: P013 | B14: 0.13 | D14: No013 | E14: 13
A15: P014 | B15: 0.14 | D15: No014 | E15: 14
A16: P015 | B16: 0.15 | D16: No015 | E16: 15
A17: P016 | B17: 0.16 | D17: No016 | E17: 16
A18: P017 | B18: 0.17 | D18: No017 | E18: 17
... A101: P100 | B101: 1 | D101: No100 | E101: 100
D102: No101 | E102: 101
D103: No102 | E103: 102
D104: No103 | E104: 103
D105: No104 | E105: 104
D106: No105 | E106: 105
D107: No106 | E107: 106
D108: No107 | E108: 107
D109: No108 | E109: 108
D110: No109 | E110: 109
D111: No110 | E111: 110
D112: No111 | E112: 111
D113: No112 | E113: 112
... D813: No812 | E813: 812

Sheet Recipes
A1: Armour | B1: Amount | C1: Structure | D1: Resource 1 | E1: Amount 1 | F1: Resource 2 | G1: Amount 2 | H1: Resource 3 | I1: Amount 3 | J1: Resource 4 | K1: Amount 4 | L1: Resource 5 | M1: Amount 5 | N1: Resource 6 | O1: Amount 6 | P1: Resource 7 | Q1: Amount 7 | R1: Resource 8 | S1: Amount 8 | T1: Resource 9 | U1: Amount 9 | V1: Resource 10 | W1: Amount 10
A2: Common Garment | B2: 1 | C2: Advanced Workbench | D2: Linen | E2: 2 | F2: Fibre | G2: 3
A3: Common Garment | B3: 1 | C3: Town Workshop | D3: Linen | E3: 2 | F3: Fibre | G3: 3
A4: Common Bottoms | B4: 1 | C4: Advanced Workbench | D4: Linen | E4: 1 | F4: Fibre | G4: 1
A5: Common Bottoms | B5: 1 | C5: Town Workshop | D5: Linen | E5: 1 | F5: Fibre | G5: 1
A6: Heavy Helmet | B6: 1 | C6: Advanced Workbench | D6: Rare Metals | E6: 3 | F6: Linen | G6: 1 | H6: Tanned Thick Leather | I6: 1 | J6: Iron Armour Plating | K6: 1 | L6: Steel Ingot | M6: 1
A7: Reinforced Helmet | B7: 1 | C7: Advanced Workbench | D7: Fibre | E7: 2 | F7: Iron Armour Plating | G7: 1 | H7: Thick Leather | I7: 1
A8: Reinforced Helmet | B8: 1 | C8: Town Workshop | D8: Fibre | E8: 2 | F8: Iron Armour Plating | G8: 1 | H8: Thick Leather | I8: 1
A9: Light Helmet | B9: 1 | C9: Workshop | D9: Fibre | E9: 2 | F9: Bronze Armour Plating | G9: 1 | H9: Thin Leather | I9: 1
A10: Light Helmet | B10: 1 | C10: Town Workshop | D10: Fibre | E10: 2 | F10: Bronze Armour Plating | G10: 1 | H10: Thin Leather | I10: 1
A11: Crude Helmet | B11: 1 | C11: Workshop | D11: Flint | E11: 1 | F11: Fibre | G11: 2
A12: Crude Helmet | B12: 1 | C12: Town Workshop | D12: Flint | E12: 1 | F12: Fibre | G12: 2
A13: Heavy Chest Armour | B13: 1 | C13: Advanced Workbench | D13: Rare Metals | E13: 6 | F13: Linen | G13: 1 | H13: Tanned Thick Leather | I13: 2 | J13: Iron Armour Plating | K13: 2 | L13: Steel Ingot | M13: 1
A14: Reinforced Chest Armour | B14: 1 | C14: Advanced Workbench | D14: Fibre | E14: 3 | F14: Iron Armour Plating | G14: 2 | H14: Thick Leather | I14: 2
A15: Reinforced Chest Armour | B15: 1 | C15: Town Workshop | D15: Fibre | E15: 3 | F15: Iron Armour Plating | G15: 2 | H15: Thick Leather | I15: 2
A16: Light Chest Armour | B16: 1 | C16: Workshop | D16: Fibre | E16: 3 | F16: Bronze Armour Plating | G16: 2 | H16: Thin Leather | I16: 2
A17: Light Chest Armour | B17: 1 | C17: Town Workshop | D17: Fibre | E17: 3 | F17: Bronze Armour Plating | G17: 2 | H17: Thin Leather | I17: 2
A18: Crude Chest Armour | B18: 1 | C18: Workshop | D18: Fibre | E18: 1 | F18: Thin Leather | G18: 1
A19: Crude Chest Armour | B19: 1 | C19: Town Workshop | D19: Fibre | E19: 1 | F19: Thin Leather | G19: 1
A20: Heavy Leg Armour | B20: 1 | C20: Advanced Workbench | D20: Rare Metals | E20: 3 | F20: Linen | G20: 1 | H20: Tanned Thick Leather | I20: 1 | J20: Iron Armour Plating | K20: 1 | L20: Steel Ingot | M20: 1
A21: Reinforced Leg Armour | B21: 1 | C21: Advanced Workbench | D21: Fibre | E21: 2 | F21: Iron Armour Plating | G21: 1 | H21: Thick Leather | I21: 1
A22: Reinforced Leg Armour | B22: 1 | C22: Town Workshop | D22: Fibre | E22: 2 | F22: Iron Armour Plating | G22: 1 | H22: Thick Leather | I22: 1
A23: Light Leg Armour | B23: 1 | C23: Workshop | D23: Fibre | E23: 2 | F23: Bronze Armour Plating | G23: 1 | H23: Thin Leather | I23: 1
A24: Light Leg Armour | B24: 1 | C24: Town Workshop | D24: Fibre | E24: 2 | F24: Bronze Armour Plating | G24: 1 | H24: Thin Leather | I24: 1
A25: Crude Leg Armour | B25: 1 | C25: Workshop | D25: Flint | E25: 1 | F25: Fibre | G25: 2
A26: Crude Leg Armour | B26: 1 | C26: Town Workshop | D26: Flint | E26: 1 | F26: Fibre | G26: 2
A28: Weapon | B28: Amount | C28: Structure | D28: Resource 1 | E28: Amount 1 | F28: Resource 2 | G28: Amount 2 | H28: Resource 3 | I28: Amount 3 | J28: Resource 4 | K28: Amount 4 | L28: Resource 5 | M28: Amount 5 | N28: Resource 6 | O28: Amount 6 | P28: Resource 7 | Q28: Amount 7 | R28: Resource 8 | S28: Amount 8 | T28: Resource 9 | U28: Amount 9 | V28: Resource 10 | W28: Amount 10
A29: Masterwork Short Sword | B29: 1 | C29: Advanced Workbench | D29: Wood Blank | E29: 1 | F29: Iron Sword Blade | G29: 1 | H29: Rare Metals | I29: 3 | J29: Lead Ingot | K29: 1 | L29: Rosin | M29: 1
A30: Superior Short Sword | B30: 1 | C30: Advanced Workbench | D30: Wood Blank | E30: 1 | F30: Iron Sword Blade | G30: 1 | H30: Rare Metals | I30: 3 | J30: Lead Ingot | K30: 1
A31: Fine Short Sword | B31: 1 | C31: Advanced Workbench | D31: Wood Blank | E31: 1 | F31: Iron Sword Blade | G31: 1 | H31: Rare Metals | I31: 3
A32: Iron Short Sword | B32: 1 | C32: Advanced Workbench | D32: Wood Blank | E32: 1 | F32: Iron Sword Blade | G32: 1
A33: Iron Short Sword | B33: 1 | C33: Town Workshop | D33: Wood Blank | E33: 1 | F33: Iron Sword Blade | G33: 1
A34: Bronze Short Sword | B34: 1 | C34: Workshop | D34: Wood Blank | E34: 1 | F34: Bronze Sword Blade | G34: 1
A35: Bronze Short Sword | B35: 1 | C35: Town Workshop | D35: Wood Blank | E35: 1 | F35: Bronze Sword Blade | G35: 1
A36: Iron Mace | B36: 1 | C36: Advanced Workbench | D36: Wood Blank | E36: 1 | F36: Iron Axe Blade | G36: 1 | H36: Rosin | I36: 1 | J36: Lead Ingot | K36: 1
A37: Iron Knife | B37: 1 | C37: Advanced Workbench | D37: Wood Blank | E37: 1 | F37: Iron Tool Blade | G37: 1
A38: Iron Knife | B38: 1 | C38: Town Workshop | D38: Wood Blank | E38: 1 | F38: Iron Tool Blade | G38: 1
A39: Crude Short Sword | B39: 1 | C39: Workshop | D39: Branches | E39: 2 | F39: Flint | G39: 2
A40: Crude Short Sword | B40: 1 | C40: Town Workshop | D40: Branches | E40: 2 | F40: Flint | G40: 2
A41: Bronze Knife | B41: 1 | C41: Workshop | D41: Bronze Tool Blade | E41: 1 | F41: Wood Blank | G41: 1
...

Sheet ResourceOverview
A1: World Resource | B1: ID | C1: Tool | D1: Description | E1: Output 1 | F1: Amount 1 | G1: Output 2 | H1: Amount 2 | I1: Output 3 | J1: Amount 3
A2: Animal Shite Pile | B2: WR001 | C2: Hands | D2: Animal Shite Pile is a resource pile created by Horse and Donkey. It despawns after 15 Minutes if not collected. | E2: Animal Shite | F2: 1
A3: Berry Bush | B3: WR002 | C3: Hands | D3: Berry Bush is a resource bush within the world of Calligo. | E3: Berries | F3: 1 | G3: Fibre | H3: 2
A4: Branch Pile | B4: WR003 | C4: Hands | D4: Branch Pile is a resource pile within the world of Calligo. | E4: Branches | F4: 1
A5: Briar Spruce Tree | B5: WR004 | C5: Stone Axe, Bronze Axe, Iron Axe, Iron Broadax | D5: The Briar Spruce Tree is a type of tree found within the world of Calligo. It has 3 stages of growth with 2 hours of time between each stage, for a total growth time of 4 hours. The amount of logs dropped by the tree change depending on its growth stage, with seeds only being dropped in the mature stage. | E5: Branches | F5: 6 | G5: Briar Spruce Log | H5: 2 | I5: Briar Spruce Seeds | J5: 1
A6: Cabbage Plant | B6: WR005 | C6: Iron Scythe | D6: Cabbage Plant is a plant that grows on a Tilled Field . It requires Cabbage Seed to plant. Cabbage plants take a total of 1.5 hours to grow. If Fertilizer is applied on the field, the growth time is reduced by 33% thus taking roughly 1 hour to grow. | E6: Cabbage | F6: 1 to 2 | G6: Cabbageseeds | H6: 1 to 3
A7: Cassiterite Chunk | B7: WR006 | C7: Bronze Pickaxe, Iron Pickaxe | D7: Cassiterite Chunk is a resource found in the underworld. It can only be found after 4 days have passed in the age. | E7: Cassiterite Ore | F7: 1
A8: Coal Chunk | B8: WR007 | C8: Bronze Pickaxe, Iron Pickaxe | D8: Coal Chunk is a resource found in the underworld. It can only be found after 3 days have passed in the age. | E8: Coal | F8: 1
A9: Dead Wood Tree | B9: WR008 | C9: Bronze Axe, Iron Axe, Iron Broadax | D9: Dead Wood Trees are a type of tree resource found within the world of Calligo. They will spawn 3 Dire Raven which will patrol close to the tree to protect it. | E9: Dead Wood Log | F9: 2
A10: Flax Plant | B10: WR009 | C10: Iron Scythe | D10: Flax Plant is a plant that grows on a Tilled Field . It requires Flax Seed to plant. Flax plants take a total of 2 hours to grow. If Fertilizer is applied on the field, the growth time is reduced by 33% thus taking roughly 1 hour, 20 minutes to grow. | E10: Flax | F10: 1
A11: Flint Pile | B11: WR010 | C11: Hands | D11: Flint Pile is a resource pile within the world of Calligo. | E11: Flint | F11: 1
A12: Hemp Plant | B12: WR011 | C12: Iron Scythe | D12: Hemp Plant is a resource that will start to spawn in Calligo 2 days into the age. After which it can be cultivated on a Tilled Field . It requires Hemp Seed for planting and need warm air temperatures to be sown. Hemp plants take a total of 3 hours to grow. If Fertilizer is applied on the field, the growth time is reduced by 33% thus taking roughly 2 hours to grow. | E12: Strong Fibre | F12: 1 | G12: Hemp Seed | H12: 1
A13: Iron Chunk | B13: WR012 | C13: Bronze Pickaxe, Iron Pickaxe | D13: Hemp Plant is a resource that will start to spawn in Calligo 2 days into the age. After which it can be cultivated on a Tilled Field . It requires Hemp Seed for planting and need warm air temperatures to be sown. Hemp plants take a total of 3 hours to grow. If Fertilizer is applied on the field, the growth time is reduced by 33% thus taking roughly 2 hours to grow. | E13: Iron Ore | F13: 1
A14: Iron Fragments Pile | B14: WR013 | C14: Bronze Pickaxe, Iron Pickaxe | D14: Iron Fragments Pile is a resource found in the underworld. | E14: Iron Ore Fragment | F14: 1
A15: Lead Fragments Pile | B15: WR014 | C15: Bronze Pickaxe, Iron Pickaxe | D15: Lead Fragments Pile is a resource pile that can be found within the world of Calligo. | E15: Lead Fragments | F15: 1
A16: Malachite Chunk | B16: WR015 | C16: Bronze Pickaxe, Iron Pickaxe | D16: Malachite Chunk is a resource found in the underworld. | E16: Malachite Ore | F16: 1
A17: Malachite Fragments Pile | B17: WR016 | C17: Flint Pickaxe, Bronze Pickaxe, Iron Pickaxe | D17: Malachite Fragments Pile is a resource pile that can be found around a Malachite Mine . | E17: Malachite Fragments | F17: 1
A18: Mireland Beech Tree | B18: WR017 | C18: Stone Axe, Bronze Axe, Iron Axe, Iron Broadax | D18: The Mireland Beech Tree is a type of tree found within the world of Calligo. It has 3 stages of growth with 2 hours of time between each stage, for a total growth time of 4 hours. The amount of logs dropped by the tree change depending on its growth stage, with seeds only being dropped in the mature stage. | E18: Branches | F18: 4 | G18: Mireland Beech Log | H18: 2 | I18: Mireland Beech Seed | J18: 1
A19: North Astrian Pine Tree | B19: WR018 | C19: Stone Axe, Bronze Axe, Iron Axe, Iron Broadax | D19: The North Astrian Pine Tree is a type of tree found within the world of Calligo. It has 3 stages of growth with 2 hours of time between each stage, for a total growth time of 4 hours. The amount of logs dropped by the tree change depending on its growth stage, with seeds only being dropped in the mature stage. | E19: Branches | F19: 4 | G19: North Astrian Pine Log | H19: 2 | I19: North Astrian Pine Seeds | J19: 1
A20: Rare Metals Pile | B20: WR019 | C20: Bronze Pickaxe, Iron Pickaxe | D20: Rare Metals Pile is a resource pile that can be found in the underworld. | E20: Rare Metals | F20: 1
A21: Relic Site | B21: WR020 | C21: Flint Pickaxe, Bronze Pickaxe, Iron Pickaxe | D21: A Relic Site is a religious victory condition structure that will spawn at random location along the current empire territory border every 1 Hour, 30 Minutes. After spawning the site will be available for mining with a pickaxe for 15 minutes before despawning. Successfully mining the site will reward you with number of Religious Relics which can be handed in at a town Bounty Board to provide both Silver and 14 religious influence per trophy. The first empire to reach 10,000 influence will earn the religious victory. | E21: Religious Relics | F21: 25
A22: Resin Pile | B22: WR021 | C22: Bronze Knife, Iron Knife | D22: Resin Pile is a resource pile that can be found in the world of Calligo. | E22: Crude Resin | F22: 1
A23: Stone Chunk | B23: WR022 | C23: Flint Pickaxe, Bronze Pickaxe, Iron Pickaxe | D23: Stone Chunk is a resource found in the underworld. Limestone has a chance to drop. | E23: Rock Slab | F23: 1 | G23: Limestone | H23: 1
A24: Stone Fragments Pile | B24: WR023 | C24: Flint Pickaxe, Bronze Pickaxe, Iron Pickaxe | D24: Stone Fragments Pile is a resource pile within the world of Calligo. | E24: Stone Off-Cuts | F24: 3 to 4
A25: Tree Stumps | B25: WR024 | C25: Stone Axe, Bronze Axe, Iron Axe, Iron Broadax | D25: Tree Stump is a resource pile. | E25: Branches | F25: 1
A26: Wheat Plant | B26: WR025 | C26: Iron Scythe | D26: Wheat Plant is a plant that grows on a Tilled Field . It requires Wheat Seed to plant. Wheat plants take a total of 1.5 hours to grow. If Fertilizer is applied on the field, the growth time is reduced by 33% thus taking roughly 1 hour to grow. | E26: Wheat Sheaf | F26: 1 to 2 | G26: Wheat Seed | H26: 1 to 3
A27: Wild Cabbage Plant | B27: WR026 | C27: Hands | D27: Wild Cabbage Plant is a plant that can be found in the world of Calligo. | E27: Cabbage Seed | F27: 1 to 2
A28: Wild Flax Plant | B28: WR027 | C28: Hands | D28: Wild Flax Plant is a plant that can be found in the world of Calligo. | E28: Flax Seed | F28: 1
A29: Wild Wheat Plant | B29: WR028 | C29: Hands | D29: Wild Wheat Plant is a plant that can be found in the world of Calligo. | E29: Wheat Seed | F29: 1 to 2
A31: Raw Resource | B31: ID | C31: Size | D31: Description
A32: Branches | B32: RR001 | C32: Small | D32: Branches are raw resources. They are among the most basic resources, used extensively throughout the war. They can also be used as fuel. Fuel duration is 30 seconds.
A33: Briar Spruce Log | B33: RR002 | C33: Big | D33: Briar Spruce Log is a raw resource.
A34: Briar Spruce Seeds | B34: RR003 | C34: Small | D34: Briar Spruce Seeds are seeds dropped by chopping down Briar Spruce Tree IconResourceWood02.png, which players can plant to grow another briar spruce tree.
A35: Cassiterite Fragments | B35: RR004 | C35: Small | D35: Cassiterite Fragments are raw resources.
A36: Coal | B36: RR005 | C36: Big | D36: Coal is a large chunk of coal that needs to be smashed before it can be smelted.
A37: Crude Resin | B37: RR006 | C37: Small | D37: Crude Resin is a raw resource. Is not stackable.
A38: Dead Wood Log | B38: RR007 | C38: Big | D38: Dead Wood Log is a raw resource.
A39: Fibre | B39: RR008 | C39: Small | D39: Fibre is a raw resource. It is among the most basic resources, used extensively throughout the war. It can also be used as fuel. Fuel duration 60 seconds.
A40: Flint | B40: RR009 | C40: Small | D40: Flint is a raw resource.
A41: Iron ore | B41: RR010 | C41: Big | D41: Iron Ore is a large chunk of iron that needs to be smashed before it can be smelted.
...
